{"comment_text": "My guess: the system keeps calling your function, and throws an exception whenever an asynchronous call needs to be made which was not yet handled. This exception is then caught inside the system to mark the asynchronous call as being done, and the next iteration starts.", "author": "amelius", "title": null, "url": null, "timestamp": 1431290612, "created_at": "2015-05-10T20:43:32.000Z", "comment_id": "9521224", "parent_id": 9520693, "story_title": "Syncify.js \u2013 Eliminates the need for callbacks in the browser", "story_id": 9519683, "story_url": "https://github.com/aldonline/syncify", "points": null}